Workbook

Sheet Key Ach. 
A1: # | B1: Project / Area | C1: Project Type | D1: Key Achievement
A2: 1 | B2: Sparta CRM | C2: In-house Project | D2: Delivered a stable release of the Sparta CRM with improved reliability and smooth operations.
A3: 2 | B3: Workgrid Enhancement | C3: In-house Project | D3: Developed and implemented the Sprint Module to enhance project and sprint management.
A4: 3 | B4: Sharooq’s Project, NWT, Nomads, Briggs, Footwear, Catesby, etc. | C4: Client Project | D4: Ensured project stability and smooth deliveries with proper CR tracking, documentation, and timely implementation.
A5: 4 | B5: FastRanking Website | C5: In-house Project | D5: Successfully developed the next-generation FastRanking website with a modern and improved solution.
A6: 5 | B6: Vee Repairs Website | C6: In-house Project | D6: Developed the next-generation Vee Repairs website with a modern and improved architecture.
A7: 6 | B7: Rabia, Sofiya, Jeleel, etc. | C7: Client Project | D7: Delivered client projects on time and maintained strong client satisfaction, reflected through 5-star Google reviews and positive feedback.
A8: 7 | B8: Client Retention & Payment Recovery | C8: Client Project | D8: Successfully retained 6 previously pending clients, strengthened relationships, delivered requirements on time, and recovered outstanding payments.
A9: 8 | B9: Sprint Retrospective & Project Management Tools | C9: In-house Project | D9: Created a Sprint Retrospective tool for management reporting and contributed to developing a next-generation project management tool for detailed project, employee, and sprint tracking.
A10: 9 | B10: Superhouse Education Foundation | C10: Client Project | D10: Successfully recovered the pending £1,000 AMC payment that had been outstanding for 2 months.
A11: 10 | B11: Client Onboarding Support | C11: Client Project | D11: Supported agents with client questionnaires and quick onboarding questions to streamline the client onboarding process.

Sheet New Projects_July
A1: Project Management Dashboard
A3: Total Projects | D3: New Projects | F3: Old Projects | H3: In-Progress | J3: Done | L3: On-Hold | N3: Backoff
A4: 28 | D4: 21 | F4: 7 | H4: 14 | J4: 9 | L4: 3 | N4: 1
D5: Total Cost | F5: Invoice Value | H5: Collected | J5: Pending | L5: Collection %
D6: =SUMPRODUCT((D34:D62<>"BackedOff")*VALUE(SUBSTITUTE(SUBSTITUTE(H34:H62,"£",""),",",""))) -> 14214.33 | F6: =SUMPRODUCT((D34:D62<>"BackedOff")*VALUE(SUBSTITUTE(SUBSTITUTE(I34:I62,"£",""),",",""))) -> 16124.8 | H6: NA | J6: NA | L6: NA
A31: Newly Added Projects
A33: Project Type | B33: Client Name | C33: Project Name | D33: Current Status | E33: Service | F33: Onboarding Date | G33: Deadline | H33: Project Cost | I33: Inc VAT (Invoice Value) | J33: Payment Frequence | K33: Collected Amount | L33: Amount Pending | M33: Comments
A34: New | B34: Reading Properties Group LTD | C34: Reading Properties Group LTD | D34: In-Progress | E34: Web Development | F34: 16th June,2026 | H34: £ 4,000.00 | I34: £ 4,000.00 | J34: NA | K34: Not Keeping Track of the Invoices. Discussed with Accounts.& Reporting Manager | L34: NA | M34: RPG Done, RDS : 80% & RF : 50%
A35: New | B35: Aspire Learning LTD | C35: Aspire Learning LTD | D35: In-Progress | E35: Web Development | H35: £ 333.33 | I35: £ 400.00 | J35: NA | K35: Not Keeping Track of the Invoices. Discussed with Accounts.& Reporting Manager | L35: NA | M35: Content Pending from Client End
A36: New | B36: GoldFinch Insulations LTD | C36: GoldFinch Insulations LTD | D36: Done | E36: Web Development | F36: 17th July,2026 | G36: 27th July,2026 | H36: £ 200.00 | I36: £ 240.00 | J36: NA | K36: Not Keeping Track of the Invoices. Discussed with Accounts.& Reporting Manager | L36: NA | M36: Done
A37: New | B37: De'osa Engg. LTD | C37: De'osa Engg. LTD | D37: On-Hold | E37: Web Development | H37: £ 400.00 | I37: £ 480.00 | J37: NA | K37: Not Keeping Track of the Invoices. Discussed with Accounts.& Reporting Manager | L37: NA | M37: Client not responding , Demo Submitted
A38: New | B38: Malvern Renovation | C38: Malvern Renovation | D38: BackedOff | E38: Web Development | H38: £ 400.00 | I38: £ 480.00 | J38: NA | K38: Not Keeping Track of the Invoices. Discussed with Accounts.& Reporting Manager | L38: NA | M38: NA
A39: New | B39: PAV'S Driving School | C39: PAV'S Driving School | D39: Done | E39: Web Development | F39: 29th July,2026 | G39: 3rd Aug,2026 | H39: £ 100.00 | I39: £ 120.00 | J39: NA | K39: Not Keeping Track of the Invoices. Discussed with Accounts.& Reporting Manager | L39: NA | M39: Done
A40: New | B40: 88 Driving School | C40: 88 Driving School | D40: Done | E40: Web Development | F40: 31st July,2026 | G40: 26th Sep,2026 | H40: £ 300.00 | I40: £ 360.00 | J40: NA | K40: Not Keeping Track of the Invoices. Discussed with Accounts.& Reporting Manager | L40: NA | M40: Done
A41: New | B41: Richmond Toto Professional Cleaning Ltd | C41: Richmond Toto Professional Cleaning Ltd | D41: Done | E41: Web Development | F41: 5th Aug,2026 | H41: £250.00 | I41: £300.00 | J41: NA | K41: Not Keeping Track of the Invoices. Discussed with Accounts.& Reporting Manager | L41: NA | M41: Done
A42: New | B42: Footwear Depot | C42: Footwear Depot | D42: In-Progress | E42: Web Development | H42: £499.00 | I42: £598.00 | J42: NA | K42: Not Keeping Track of the Invoices. Discussed with Accounts.& Reporting Manager | L42: NA | M42: In Progress , 80%
A43: New | B43: Briggs Industrial Footwear Limited | C43: Briggs Industrial Footwear Limited | D43: In-Progress | E43: Web Development | H43: £599.00 | I43: £718.80 | J43: NA | K43: Not Keeping Track of the Invoices. Discussed with Accounts.& Reporting Manager | L43: NA | M43: In Progress , 80%
A44: New | B44: Sofiya Designs Acedemy Ltd | C44: Sofiya Designs Acedemy Ltd | D44: Done | E44: Web Development | F44: 19th Aug,2026 | H44: £600.00 | I44: £720.00 | J44: NA | K44: Not Keeping Track of the Invoices. Discussed with Accounts.& Reporting Manager | L44: NA | M44: Done
A45: New | B45: Mountains Of Glory | C45: Mountains Of Glory | D45: On-Hold | E45: Web Development | H45: £416.00 | I45: £500.00 | J45: NA | K45: Not Keeping Track of the Invoices. Discussed with Accounts.& Reporting Manager | L45: NA | M45: NA
A46: New | B46: Spot Cleaners Ltd | C46: Spot Cleaners Ltd | D46: In-Progress | E46: Web Development | F46: 31st Aug,2026 | H46: £350.00 | I46: £420.00 | J46: NA | K46: Not Keeping Track of the Invoices. Discussed with Accounts.& Reporting Manager | L46: NA | M46: Testing is in progress
A47: New | B47: Sofiya Designs Ltd | C47: Sofiya Designs Ltd | D47: Done | E47: Web Development | F47: 02nd Sep,2026 | H47: £350.00 | I47: £420.00 | J47: NA | K47: Not Keeping Track of the Invoices. Discussed with Accounts.& Reporting Manager | L47: NA | M47: Done
A48: New | B48: Altai Mountain | C48: Altai Mountain | D48: In-Progress | E48: Web Development | F48: 14th Sep,2026 | G48: 8th Oct,2026 | H48: £300.00 | I48: £360.00 | J48: NA | K48: Not Keeping Track of the Invoices. Discussed with Accounts.& Reporting Manager | L48: NA | M48: Review pending from Client end.
A49: New | B49: Max Out Tutoring | C49: Max Out Tutoring | D49: In-Progress | E49: Web Development | F49: 15th Sep,2026 | G49: 9th Oct,2026 | H49: £500.00 | I49: £600.00 | J49: NA | K49: Not Keeping Track of the Invoices. Discussed with Accounts.& Reporting Manager | L49: NA | M49: Bug resolution
A50: New | B50: Optimum Global link Landing Page | C50: Optimum Global link Landing Page | D50: In-Progress | E50: Web Development | F50: 21th Sep, 2026 | G50: 29th Sep,2026 | H50: £100.00 | I50: £120.00 | J50: NA | K50: Not Keeping Track of the Invoices. Discussed with Accounts.& Reporting Manager | L50: NA | M50: Done
A51: New | B51: Burton Driving School | C51: Burton Driving School | D51: In-Progress | E51: Web Development | F51: 29th Sep, 2026 | H51: £250.00 | I51: £300.00 | J51: NA | K51: Not Keeping Track of the Invoices. Discussed with Accounts.& Reporting Manager | L51: NA | M51: Demo review pending from Client end
A52: New | B52: Party Supplys Ltd | C52: Party Supplys Ltd | D52: On-Hold | E52: Web Development | F52: 28th Sep,2026 | H52: £300.00 | I52: £360.00 | J52: NA | K52: Not Keeping Track of the Invoices. Discussed with Accounts.& Reporting Manager | L52: NA | M52: Assigned
A53: New | B53: Boiler Gas Tech Limited | C53: Boiler Gas Tech Limited | D53: To-Do | E53: Web Development | F53: 07th Oct, 2026 | H53: £333.00 | I53: £400.00 | J53: NA | K53: Not Keeping Track of the Invoices. Discussed with Accounts.& Reporting Manager | L53: NA | M53: Not Assigned
A54: New | B54: Connect Driving School Ltd | C54: Connect Driving School Ltd | D54: To-Do | E54: Web Development | F54: 06th Oct, 2026 | H54: £350.00 | I54: £420.00 | J54: NA | K54: Not Keeping Track of the Invoices. Discussed with Accounts.& Reporting Manager | L54: NA | M54: Not Assigned
A55: New | B55: UK Admission Manchester | C55: UK Admission Manchester | D55: To-Do | E55: Web Development | F55: 21st Oct, 2026 | H55: £200.00 | I55: £240.00 | J55: NA | K55: Not Keeping Track of the Invoices. Discussed with Accounts.& Reporting Manager | L55: NA | M55: Not Assigned
A56: Old | B56: Optimum Global Care | C56: Optimum Global Care | D56: Done | E56: Web Development | F56: NA | G56: 15th Sep,2026 | H56: £334.00 | I56: £400.00 | J56: NA | K56: Not Keeping Track of the Invoices. Discussed with Accounts.& Reporting Manager | L56: NA | M56: Done
A57: Old | B57: Corby Motors | C57: Corby Motors | D57: Done | E57: Web Development | F57: NA | H57: £750.00 | I57: £900.00 | J57: NA | K57: Not Keeping Track of the Invoices. Discussed with Accounts.& Reporting Manager | L57: NA | M57: Done
A58: Old | B58: Eagle Properties | C58: Eagle Properties | D58: In-Progress | E58: Web Development | F58: NA | H58: £450.00 | I58: £540.00 | J58: NA | K58: Not Keeping Track of the Invoices. Discussed with Accounts.& Reporting Manager | L58: NA | M58: Ready to go live
A59: Old | B59: Ace Learning Plus Limited | C59: Ace Learning Plus Limited | D59: Done | E59: Web Development | F59: NA | G59: 17th Sep,2026 | H59: £500.00 | I59: £599.00 | J59: NA | K59: Not Keeping Track of the Invoices. Discussed with Accounts.& Reporting Manager | L59: NA | M59: Done
A60: Old | B60: GreySon Studios | C60: GreySon Studios | D60: In-Progress | E60: Web Development | F60: NA | H60: £500.00 | I60: £599.00 | J60: NA | K60: Not Keeping Track of the Invoices. Discussed with Accounts.& Reporting Manager | L60: NA | M60: Ready to go live
A61: Old | B61: Stabilus Safety GmbH | C61: Stabilus Safety GmbH | D61: In-Progress | E61: Web Development | F61: 27th July, 2025 | H61: £650.00 | I61: £650.00 | J61: NA | K61: Not Keeping Track of the Invoices. Discussed with Accounts.& Reporting Manager | L61: NA | M61: UAT-SignOff Pending
A62: Old | B62: Varsity Music | C62: Varsity Music | D62: In-Progress | E62: Web Development | F62: 13th March, 2025 | H62: £300.00 | I62: £360.00 | J62: NA | K62: Not Keeping Track of the Invoices. Discussed with Accounts.& Reporting Manager | L62: NA | M62: Client not responding , Site is ready

Sheet AI Projects
A1: S.No. | B1: Project Name | C1: Customer | D1: Start Date | E1: Deadline | F1: Members | G1: Status | H1: Project Categories
A2: 1 | B2: Sparta Telecom - Data Management System [ DMA ] | C2: Sparta | D2: NA | E2: NA | F2: Shivam Backend Dev | G2: In Progress | H2: Inhouse
A3: 2 | B3: SEO Audit Tool — Real-Time Audit & AI Business Suggestions | C3: Sparta | D3: NA | E3: NA | F3: Shivam Backend Dev | G3: In Progress | H3: Inhouse
A4: 3 | B4: AI-Agent — TalkTalk Line Classification | C4: Sparta | D4: NA | E4: NA | F4: Shivam Backend Dev | G4: In Progress | H4: Inhouse
A5: 4 | B5: AI-Agent — Ameyo Voice Log Downloader | C5: Sparta | D5: NA | E5: NA | F5: Shivam Backend Dev | G5: In Progress | H5: Inhouse
A6: 6 | B6: VeeRepairs CRM — ETE Quality Automation | C6: Sparta | D6: NA | E6: NA | F6: Shivam Backend Dev | G6: In Progress | H6: Inhouse
A7: 7 | B7: AI Automation — Ameyo Call Details Report Downloader | C7: Sparta | D7: NA | E7: NA | F7: Shivam Backend Dev | G7: In Progress | H7: Inhouse
A8: 8 | B8: AI Agent - Call History Downloader — Ameyo | DMA Phase 3 | C8: Sparta | D8: NA | E8: NA | F8: Shivam Backend Dev | G8: In Progress | H8: Inhouse
A9: 9 | B9: FastRanking & VeeRepairs || QAAI — AI-Powered Quality Automation | C9: Sparta | D9: NA | E9: NA | F9: Shivam Backend Dev | G9: In Progress | H9: Inhouse
A10: 10 | B10: Hot Lead Automation | B2B Lead Generation | C10: Sparta | D10: NA | E10: NA | F10: Shivam Backend Dev | G10: In Progress | H10: Inhouse
A11: 11 | B11: HR - Sparta Recruit | AI-Powered Recruitment System | C11: Sparta | D11: NA | E11: NA | F11: Shivam Backend Dev | G11: In Progress | H11: Inhouse
A12: 12 | B12: Digital Marketing Hub | SEO Performance & Intelligence Platform | C12: Sparta | D12: NA | E12: NA | F12: Shivam Backend Dev | G12: UAT | H12: Inhouse
A13: 13 | B13: Backlink Checker Tool | Automated SEO Verification | C13: Sparta | D13: NA | E13: NA | F13: Shivam Backend Dev | G13: UAT | H13: Inhouse
... A19: 19.637363 | B19: QA-SAAS Platform | AI-Powered Quality Assurance | C19: Sparta | D19: NA | E19: NA | F19: Shivam Backend Dev | G19: TBD | H19: Inhouse

Sheet Sharooq & AllenHouse
A1: Project | B1: Task / Scope | C1: Status | D1: Category | E1: Work Hours
A2: Sharooq Projects
A3: Catesby England | B3: Redesign the website, add additional features and pages, and add new products. | C3: In Progress | D3: CR | E3: 6h
A4: Silver Street London | B4: Update product images (listed items), add new features and sections, and add new products. | C4: In Progress | D4: CR | E4: 4h
A5: Northwest Territory | B5: Update product images (listed items), change section placements, and add new products. | C5: Daily | D5: CR | E5: 4h
A6: Amen Shoes | B6: Redesign the website and add additional features and pages. | C6: In Progress | D6: CR | E6: 2h
A7: Marketplace Website | B7: Stock updates. | C7: Weekly | D7: AMC | E7: 2h
A8: Get Set Cook | B8: Design and create a new page and add new products. | C8: New CR | D8: CR | E8: 6h
A9: Nomads – Mimansa
A10: Nomads Clothing | B10: New CR - Product Upload | C10: N/A | D10: NA | E10: NA
A11: Nomads Trade (Wholesale) | B11: Removed the hidden feature, making all products visible to customers while keeping prices restricted to logged-in users. | C11: Done | D11: CR | E11: 6h
A14: Project | B14: Task / Scope ( 9th July, 26 ) | C14: Status | D14: Category | E14: Work Hours
A15: Sharooq Projects
A16: Catesby England | B16: Creating MEGA Menu | C16: In Progress | D16: CR | E16: 4h
A17: Silver Street London | B17: Update product images (listed items) | C17: In Progress | D17: CR | E17: 3h
A22: AllenHouse
A23: APS Websites | B23: Update the H1 tags, Slug , Blogs for all the 7 AllenHouse websites. | C23: In Progress | D23: CR | E23: 3h
A27: Requirement | B27: Type | C27: CR Required? | D27: Reason | E27: Work Hours
A28: Remove the date from all booking banners | B28: UI/Design Change | C28: ✅ Yes | D28: Existing design is being modified. | E28: 4h
A29: Add a new "Booking Type" field | B29: New Feature | C29: ✅ Yes | D29: Introduction of a new form field and workflow.
A30: Position the field below Email and above Booking Date | B30: UI/Layout Change | C30: ✅ Yes | D30: Changes the existing form structure.
A31: Add options: Individual, Small Group, Full Table | B31: Feature Enhancement | C31: ✅ Yes | D31: New booking categories affecting functionality.
A32: Change Booking Date to dropdown for Individual & Small Group | B32: Functional Change | C32: ✅ Yes | D32: Existing booking behaviour is being modified.
A33: Show calendar picker for Full Table | B33: Functional Change | C33: ✅ Yes | D33: New conditional functionality.
A34: Restrict Full Table bookings to 15+ days | B34: Business Logic | C34: ✅ Yes | D34: New validation/business rule.
A35: Allow existing Full Table events within 15 days to remain bookable | B35: Advanced Business Logic | C35: ✅ Yes | D35: Additional booking workflow and database logic.
A36: Send booking details to Gmail after submission | B36: Notification Feature | C36: ✅ Yes | D36: New email notification recipient/functionality.
A37: Send booking details to WhatsApp after submission | B37: Third-party Integration | C37: ✅ Yes | D37: New WhatsApp notification integration.

Sheet Client Projects
A1: S.No. | B1: Project Name | C1: Customer | D1: Start Date | E1: Deadline | F1: Members | G1: Status | H1: Project Categories | I1: Comments | J1: Contacts | K1: Status
A2: 1 | B2: FCL(firstclasslearning) | C2: FCL(firstclasslearning) | D2: 46158 | E2: 46174 | F2: Vipin, Avinash, Nikhil & Abhijeet | G2: Finished | H2: Wordpress | I2: Camping is live.
A3: 2 | B3: Surge Production | C3: Surge Production | D3: 46153 | E3: 46184 | F3: Deepak , Abhijeet | G3: UAT | H3: Wordpress | I3: Waiting for client response - UAT Pending from client side. | J3: info.surgeproductions@gmail.com | K3: Mail sent
A4: 3 | B4: Nomads Clothing | C4: Nomads Clothing | D4: 46156 | E4: 46186 | F4: NWNikhil Web Developer | G4: Finished | H4: Shopify | I4: Deployed Successfully, Taking followup from the client is everything is good at their side.
A5: 4 | B5: APS-CMS-MIGRATION | C5: Allen House | D5: 46167 | E5: 46189 | F5: Abhijeet , Vani , Suraj , Raunik & Nikhil | G5: Finished | H5: Custom | I5: Done
A6: 5 | B6: Varsity Audio Visuals | C6: Varsity Audio Visuals | D6: 46185 | E6: 46192 | F6: AWADAman Web Developer, Avinash Designer | G6: In Progress | H6: Wordpress | I6: In progress, team is working on homepage and once that is done team needs to test the same. | J6: <dhruv@varsityaudiovisuals.com><info@varsityaudiovisuals.com>
A7: 6 | B7: Eagle Properties | C7: Eagle Properties | D7: 46178 | E7: 46193 | F7: Deepak Web Developer | G7: In Progress | H7: Wordpress | I7: Need images from Avinash for the add-ons services, ETA : 29th June, 2026 | J7: kashif@eaglepropertycare.co.uk
A8: 7 | B8: FH Furniture | C8: FH Furniture | D8: 46073 | E8: 46183 | F8: Nikhil, Deepak & Abhijeet | G8: In Progress | H8: Shopify | I8: Need to follow-up regarding the client. | J8: faith.fhfurniture@gmail.com | K8: Mail sent
A9: 8 | B9: Landing Page Creation | C9: DrivewithGreta | D9: 46185 | E9: 46186 | F9: Deepak | G9: Finished | H9: Wordpress | I9: Done.
A10: 9 | B10: Briggs Safety Wear | C10: SEO - Briggs Safety Wear | D10: 27-March-2026 | E10: 15-April-2026 | F10: Aman | G10: Finished | H10: Wordpress | I10: Done
A11: 10 | B11: LAYLA GORDON | C11: LAYLA GORDON | D11: 28-March-2026 | E11: 15-April-2026 | F11: Aman | G11: Finished | H11: Wordpress | I11: Done
A12: 11 | B12: RBD Driving School | C12: RBD Driving School | D12: 02-April-2026 | E12: 15-April-2026 | F12: ASDWAbhijeet Singh Software Tester, Deepak Web Developer | G12: In Progress | H12: Shopify | I12: Demo Deployed, But no response from the client side
A13: 12 | B13: 4 Corners Cleaning Services Ltd | C13: 4 Corners Cleaning Services Ltd | D13: 24-February-2026 | E13: 15-April-2026 | F13: ASAbhijeet Singh Software Tester | G13: In Progress | H13: Wordpress | I13: No Response from Client | J13: red_scorpion5@hotmail.co.uk | K13: Mail sent
A14: 13 | B14: OBIsonic Digital Photography | C14: OBIsonic Digital Photography | D14: 12-February-2026 | E14: 15-April-2026 | F14: ASAbhijeet Singh Software Tester | G14: In Progress | H14: Wordpress | I14: No Response from Client | J14: contact@obisonicdp.co.uk | K14: Mail sent
A15: 14 | B15: Greyson Studios | C15: Mr. Matthew Elegbede | D15: 10-March-2026 | E15: 15-April-2026 | F15: DWDeepak Web Developer | G15: In Progress | H15: Wordpress | I15: Waiting for client response - Need to followup. | J15: matthewelegbede99@gmail.com | K15: Mail sent
A16: 15 | B16: JEWELLERY DESIGN CENTRE LIMITED | C16: JEWELLERY DESIGN CENTRE LIMITED | D16: 16-April-2026 | E16: 20-May-2026 | F16: DWAWDeepak Web Developer, Aman Web Developer | G16: Finished | H16: Shopify | I16: Done
A17: 16 | B17: NWT | C17: NWT | D17: 21-January-2026 | E17: 30-May-2026 | F17: Aman | G17: Finished | H17: Shopify | I17: Done
A18: 17 | B18: Jans Solutions Ltd | C18: Jans Solutions Ltd | D18: 24-February-2026 | E18: 30-May-2026 | F18: Aman | G18: Finished | H18: Wordpress | I18: Done
A19: 18 | B19: Nomads Saige | C19: Nomads Saige | D19: 02-April-2026 | E19: 05-June-2026 | F19: Aman | G19: Finished | H19: Shopify | I19: Done
A20: 19 | B20: Silver Street London | C20: Silver Street London | D20: 06-April-2026 | E20: 10-June-2026 | F20: Aman | G20: Finished | H20: Shopify | I20: Done
A21: 20 | B21: Varsity Audio Visuals | C21: Varsity Audio Visuals | D21: 12-June-2026 | E21: 19-June-2026 | F21: AWADAman Web Developer, Avinash Designer | G21: Finished | H21: Wordpress | I21: Done
A22: 21 | B22: AMEN SHOES | C22: AMEN SHOES | D22: 24-January-2026 | E22: 30-June-2026 | F22: Aman | G22: Finished | H22: Shopify | I22: Done
A23: 22 | B23: Allen Group - DPS | C23: Allen House | D23: 30-March-2026 | E23: 30-June-2026 | F23: Suraj, Raunik , Abhijeet & Vani | G23: Finished | H23: Custom | I23: Done
A24: 23 | B24: Allen House | C24: Allen House | D24: 01-March-2026 | E24: 22-July-2026 | F24: Suraj, Raunik , Abhijeet & Vani | G24: Finished | H24: Custom | I24: Done
A25: 24 | B25: Allen Group - Allenkids | C25: Allen House | D25: 30-March-2026 | E25: 31-July-2026 | F25: Suraj, Raunik , Abhijeet & Vani | G25: Finished | H25: Custom | I25: Done
A26: 25 | B26: READING PROPERTIES GROUP LTD | C26: Reading Properties Group | D26: 16-June-2026 | E26: 16-September-2026 | F26: Sandeep , Avinash , Abhijeet, Deepak & Aman | G26: TO-DO | H26: Wordpress | I26: In Progress
A27: 26 | B27: CATESBY ENGLAND | C27: CATESBY ENGLAND | D27: 21-January-2026 | E27: 31-July-2027 | F27: Aman & Nikhil | G27: Finished | H27: Shopify | I27: Done
A28: 27 | B28: Nomads Trade Website | C28: Nomads Trade Website | D28: 14-October-2025 | E28: 46203 | F28: Nikhil | G28: Finished | H28: Shopify | I28: Done
A29: 28 | B29: MARKETPLACE | C29: MARKETPLACE | D29: 21-January-2026 | E29: 46203 | F29: Aman | G29: Finished | H29: Shopify | I29: Done
A30: 29 | B30: Stabilus | C30: Stabilus | D30: 11-December-2025 | E30: 46203 | F30: ASAWAbhijeet Singh Software Tester, Aman Web Developer | G30: Finished | H30: Shopify | I30: Done
A31: 30 | B31: FOOTWEAR DEPOT - 1 | C31: FOOTWEAR DEPOT - 1 | D31: =VLOOKUP($B$31,Sheet1!$B$1:$I$74,4,0) -> 11-February-2026 | E31: =VLOOKUP($B$31,Sheet1!$B$1:$I$74,5,0) -> 13-February-2026 | F31: =VLOOKUP($B$31,Sheet1!$B$1:$I$74,6,0) -> AWNWAman Web Developer, Nikhil Web Developer | G31: Finished | H31: =VLOOKUP(B:B,Sheet1!$B$1:$I$74,8,0) -> Shopify | I31: Done
A32: 31 | B32: EA Driving School | C32: EA Driving School | D32: =VLOOKUP($B$32,Sheet1!$B$1:$I$74,4,0) -> 27-October-2025 | E32: =VLOOKUP(B:B,Sheet1!$B$1:$I$74,5,0) -> 09-April-2026 | F32: =VLOOKUP(B:B,Sheet1!$B$1:$I$74,6,0) -> ASAbhijeet Singh Software Tester | G32: Finished | H32: =VLOOKUP(B:B,Sheet1!$B$1:$I$74,8,0) -> Wordpress | I32: Done
A33: 32 | B33: RRJ Design | C33: RRJ Design | D33: =VLOOKUP($B$33,Sheet1!$B$1:$I$74,4,0) -> 24-February-2026 | E33: =VLOOKUP(B:B,Sheet1!$B$1:$I$74,5,0) -> 09-April-2026 | F33: =VLOOKUP(B:B,Sheet1!$B$1:$I$74,6,0) -> ASDWAbhijeet Singh Software Tester, Deepak Web Developer | G33: Finished | H33: =VLOOKUP(B:B,Sheet1!$B$1:$I$74,8,0) -> Wordpress | I33: Done
A34: 33 | B34: Agid Van | C34: Agid Van | D34: =VLOOKUP(B:B,Sheet1!$B$1:$I$74,4,0) -> 03-October-2025 | E34: =VLOOKUP(B:B,Sheet1!$B$1:$I$74,5,0) -> 13-April-2026 | F34: =VLOOKUP(B:B,Sheet1!$B$1:$I$74,6,0) -> ASAWAbhijeet Singh Software Tester, Aman Web Developer | G34: Finished | H34: =VLOOKUP(B:B,Sheet1!$B$1:$I$74,8,0) -> Wordpress | I34: Done
A35: 34 | B35: ACE LEARNING PLUS | C35: ACE LEARNING PLUS | D35: =VLOOKUP(B:B,Sheet1!$B$1:$I$74,4,0) -> 02-March-2026 | E35: =VLOOKUP(B:B,Sheet1!$B$1:$I$74,5,0) -> 15-April-2026 | F35: =VLOOKUP(B:B,Sheet1!$B$1:$I$74,6,0) -> AWASAman Web Developer, Abhijeet Singh Software Tester | G35: Finished | H35: =VLOOKUP(B:B,Sheet1!$B$1:$I$74,8,0) -> Wordpress | I35: Done
A36: 35 | B36: Boiler Gas Tech | C36: Boiler Gas Tech | D36: =VLOOKUP(B:B,Sheet1!$B$1:$I$74,4,0) -> 07-October-2025 | E36: =VLOOKUP(B:B,Sheet1!$B$1:$I$74,5,0) -> 15-April-2026 | F36: =VLOOKUP(B:B,Sheet1!$B$1:$I$74,6,0) -> +1 | G36: Finished | H36: =VLOOKUP(B:B,Sheet1!$B$1:$I$74,8,0) -> Wordpress | I36: Done
A37: 36 | B37: Julian Taxi | C37: Julian Taxi | D37: =VLOOKUP(B:B,Sheet1!$B$1:$I$74,4,0) -> 16-October-2025 | E37: =VLOOKUP(B:B,Sheet1!$B$1:$I$74,5,0) -> 15-April-2026 | F37: =VLOOKUP(B:B,Sheet1!$B$1:$I$74,6,0) -> ASAbhijeet Singh Software Tester | G37: Finished | H37: =VLOOKUP(B:B,Sheet1!$B$1:$I$74,8,0) -> Wordpress | I37: Done
A38: 37 | B38: Auto Market Place | C38: Auto Market Place | D38: =VLOOKUP(B:B,Sheet1!$B$1:$I$74,4,0) -> 29-November-2025 | E38: =VLOOKUP(B:B,Sheet1!$B$1:$I$74,5,0) -> 15-April-2026 | F38: =VLOOKUP(B:B,Sheet1!$B$1:$I$74,6,0) -> DWNWDeepak Web Developer, Nikhil Web Developer | G38: Finished | H38: =VLOOKUP(B:B,Sheet1!$B$1:$I$74,8,0) -> Wordpress | I38: Done
A39: 38 | B39: Dialogue Fosters | C39: Dialogue Fosters | D39: =VLOOKUP(B:B,Sheet1!$B$1:$I$74,4,0) -> 14-October-2025 | E39: =VLOOKUP(B:B,Sheet1!$B$1:$I$74,5,0) -> 15-April-2026 | F39: =VLOOKUP(B:B,Sheet1!$B$1:$I$74,6,0) -> AWAman Web Developer | G39: Finished | H39: =VLOOKUP(B:B,Sheet1!$B$1:$I$74,8,0) -> Wordpress | I39: Done
A40: 39 | B40: Wood and Home 99 Location pages | C40: Wood and Home 99 Location pages | D40: =VLOOKUP(B:B,Sheet1!$B$1:$I$74,4,0) -> 22-October-2025 | E40: =VLOOKUP(B:B,Sheet1!$B$1:$I$74,5,0) -> 15-April-2026 | F40: =VLOOKUP(B:B,Sheet1!$B$1:$I$74,6,0) -> ASAbhijeet Singh Software Tester | G40: Finished | H40: =VLOOKUP(B:B,Sheet1!$B$1:$I$74,8,0) -> Wordpress | I40: Done
...

Sheet ProjectDash
A1: FastRanking OnBoarding Project Report
D4: On Going Client Project Status Report
U5: All FastRanking Project Status Report
A6: Status | B6: Count of S.No. | R6: Status | S6: Sum of S.No.
A7: Finished | B7: 41 | R7: In Progress | S7: 431
A8: In Progress | B8: 12 | R8: Not Started | S8: 235
A9: On Hold | B9: 4 | R9: UAT | S9: 37
A10: UAT | B10: 2
R24: Project Categories | S24: Sum of S.No.
A25: Project Categories | B25: Count of S.No. | R25: Custom | S25: 124
A26: Custom | B26: 6 | R26: Inhouse | S26: 285
A27: Inhouse | B27: 2 | R27: Shopify | S27: 224
A28: Shopify | B28: 15 | R28: Wordpress | S28: 70
A29: Wordpress | B29: 36

Sheet 29th_June_Report_CP
D2: On Going Client Project Status Report
A3: Status | B3: Sum of S.No.
A4: Finished | B4: 1370
A5: In Progress | B5: 93
A6: On Hold | B6: 813
A7: UAT | B7: 2

Sheet Sheet1
A1: S.No. | B1: Project Name | C1: Customer | D1: Tags | E1: Start Date | F1: Deadline | G1: Members | H1: Status | I1: Project Categories | J1: Actions
A2: 3 | B2: CLARITY COMPARE LIMITED | C2: CLARITY COMPARE LIMITED | E2: 13-October-2025 | F2: 13-October-2025 | G2: ASAbhijeet Singh Software Tester | H2: Finished | I2: Wordpress
A3: 4 | B3: Rashid driving school | C3: Rashid driving school | E3: 31-October-2025 | F3: 31-October-2025 | G3: +1 | H3: Finished | I3: Wordpress
A4: 5 | B4: FOOTWEAR DEPOT - 1 | C4: FOOTWEAR DEPOT - 1 | E4: 11-February-2026 | F4: 13-February-2026 | G4: AWNWAman Web Developer, Nikhil Web Developer | H4: Finished | I4: Shopify
A5: 6 | B5: Best Value Auto | C5: Best Value Auto | E5: 16-October-2025 | F5: 08-April-2026 | G5: ASAbhijeet Singh Software Tester | H5: Finished | I5: Wordpress
A6: 7 | B6: CouloneStone | C6: SEO - Coulon Stone | E6: 13-February-2026 | F6: 08-April-2026 | G6: +2 | H6: Finished | I6: Wordpress
A7: 8 | B7: Sustainable Packaging Supplies Ltd | C7: Sustainable Packaging Supplies Ltd | E7: 03-October-2025 | F7: 09-April-2026 | G7: +1 | H7: Finished | I7: Wordpress
A8: 9 | B8: J2R safety | C8: J2R safety | E8: 14-October-2025 | F8: 09-April-2026 | G8: ASAbhijeet Singh Software Tester | H8: Finished | I8: Wordpress
A9: 10 | B9: EA Driving School | C9: EA Driving School | E9: 27-October-2025 | F9: 09-April-2026 | G9: ASAbhijeet Singh Software Tester | H9: Finished | I9: Wordpress
A10: 11 | B10: RRJ Design | C10: RRJ Design | E10: 24-February-2026 | F10: 09-April-2026 | G10: ASDWAbhijeet Singh Software Tester, Deepak Web Developer | H10: Finished | I10: Wordpress
A11: 12 | B11: Agid Van | C11: Agid Van | E11: 03-October-2025 | F11: 13-April-2026 | G11: ASAWAbhijeet Singh Software Tester, Aman Web Developer | H11: Finished | I11: Wordpress
A12: 13 | B12: Greyson Studios | C12: Mr. Matthew Elegbede | E12: 10-March-2026 | F12: 15-April-2026 | G12: DWDeepak Web Developer | H12: In Progress | I12: Wordpress
A13: 14 | B13: Briggs Safety Wear | C13: SEO - Briggs Safety Wear | E13: 27-March-2026 | F13: 15-April-2026 | G13: +1 | H13: In Progress | I13: Wordpress
... A26: 27 | B26: Veedux Production | C26: Veedux Production | E26: 25-October-2025 | F26: 15-April-2026 | G26: ASAbhijeet Singh Software Tester | H26: Finished | I26: Wordpress
A27: 28 | B27: Eden's Edge | C27: Eden's Edge | E27: 16-February-2026 | F27: 15-April-2026 | H27: Finished | I27: Wordpress
A28: 29 | B28: Kitchen 3D Limited | C28: Kitchen 3D Limited | E28: 17-December-2025 | F28: 15-April-2026 | G28: ASAbhijeet Singh Software Tester | H28: Finished | I28: Wordpress
A29: 30 | B29: Graphic Design Print | C29: Graphic Design Print | E29: 08-December-2025 | F29: 15-April-2026 | G29: DWDeepak Web Developer | H29: Finished | I29: Wordpress
A30: 31 | B30: Wood and Home | C30: Wood and Home | E30: 12-January-2026 | F30: 15-April-2026 | G30: ASAbhijeet Singh Software Tester | H30: Finished | I30: Wordpress
A31: 32 | B31: Qube Architects | C31: Qube Architects | E31: 19-January-2026 | F31: 15-April-2026 | H31: Finished | I31: Wordpress
A32: 33 | B32: SOS Plumbing Services | C32: SOS Plumbing Services | E32: 30-January-2026 | F32: 15-April-2026 | G32: NWNikhil Web Developer | H32: Finished | I32: Wordpress
A33: 34 | B33: Get Set Cook | C33: Get Set Cook | E33: 04-February-2026 | F33: 15-April-2026 | G33: NWNikhil Web Developer | H33: Finished | I33: Wordpress
A34: 36 | B34: RBD Driving School | C34: RBD Driving School | E34: 02-April-2026 | F34: 15-April-2026 | G34: ASDWAbhijeet Singh Software Tester, Deepak Web Developer | H34: Not Started | I34: Shopify
A35: 37 | B35: XSPEED ENGINES | C35: XSPEED ENGINES | E35: 30-January-2026 | F35: 17-April-2026 | G35: ASNWAbhijeet Singh Software Tester, Nikhil Web Developer | H35: On Hold | I35: Custom
A36: 38 | B36: Nelson News | C36: Nelson News | E36: 10-April-2026 | F36: 18-April-2026 | G36: AWAman Web Developer | H36: Finished | I36: Wordpress
A37: 39 | B37: Solar Panel Bird Proofing Ken | C37: Deepak Pachauri | E37: 18-March-2026 | F37: 20-April-2026 | G37: +1 | H37: Finished | I37: Wordpress
A38: 40 | B38: Corby Motors | C38: Corby Motors | E38: 23-February-2026 | F38: 20-April-2026 | G38: DWNWDeepak Web Developer, Nikhil Web Developer | H38: On Hold | I38: Wordpress
A39: 41 | B39: Kent Wasp Control | C39: Pallavi | E39: 16-March-2026 | F39: 24-April-2026 | G39: DWAWDeepak Web Developer, Aman Web Developer | H39: Finished | I39: Wordpress
A40: 42 | B40: Patrick Shoes | C40: Patrick Shoes | E40: 13-April-2026 | F40: 24-April-2026 | G40: DWVFDeepak Web Developer, Vani Frontend developer | H40: Finished | I40: Custom
A41: 46 | B41: Adam's Painting & Decorating | C41: Adam's Painting & Decorating | E41: 13-March-2026 | F41: 16-May-2026 | G41: +1 | H41: Finished | I41: Wordpress
A42: 47 | B42: Allen House - FRANCHISE LANDING PAGE PROJECT | C42: Allen House | E42: 30-April-2026 | F42: 16-May-2026 | G42: +4 | H42: Finished | I42: Custom
A43: 50 | B43: JEWELLERY DESIGN CENTRE LIMITED | C43: JEWELLERY DESIGN CENTRE LIMITED | E43: 16-April-2026 | F43: 20-May-2026 | G43: DWAWDeepak Web Developer, Aman Web Developer | H43: In Progress | I43: Shopify
... A64: 94 | B64: CATESBY ENGLAND | C64: CATESBY ENGLAND | E64: 21-January-2026 | F64: 31-July-2027 | G64: +2 | H64: In Progress | I64: Shopify
A65: 97 | B65: MARKETPLACE | C65: MARKETPLACE | E65: 21-January-2026 | G65: +1 | H65: In Progress | I65: Shopify
A66: 98 | B66: Nomads Trade Website | C66: Nomads Trade Website | E66: 14-October-2025 | G66: +1 | H66: In Progress | I66: Shopify
A67: 103 | B67: Stabilus | C67: Stabilus | E67: 11-December-2025 | G67: ASAWAbhijeet Singh Software Tester, Aman Web Developer | H67: Not Started | I67: Shopify
A68: 104 | B68: SSL | C68: SSL | E68: 28-January-2026 | G68: AWNWAman Web Developer, Nikhil Web Developer | H68: Finished | I68: Shopify
A69: 105 | B69: iDrive Auto | C69: iDrive Auto | E69: 11-December-2025 | G69: AWAman Web Developer | H69: Finished | I69: Wordpress
A70: 106 | B70: Optimum Global Care | C70: Optimum Global Care | E70: 09-October-2025 | H70: On Hold | I70: Wordpress
A71: 107 | B71: Know & Grow Tutors | C71: Know & Grow Tutors | E71: 14-October-2025 | G71: NWNikhil Web Developer | H71: Finished | I71: Wordpress
A72: 108 | B72: Mk Global Consultant | C72: Mk Global Consultant | E72: 06-October-2025 | G72: +2 | H72: Finished | I72: Wordpress
...

Sheet Sheet2
A1: Row Labels | B1: Sum of S.No.
A2: Backlink Checker Tool | Automated SEO Verification | B2: 13
A3: UAT | B3: 13
A4: Content Writing AI-Powered SEO Content Automation | B4: 15
A5: UAT | B5: 15
A6: Keyword Indexing Tool | Automated Rank Checking | B6: 14
A7: UAT | B7: 14
A8: Management Task | B8: 16.373626
A9: UAT | B9: 16.373626
A10: AI Agent - Call History Downloader — Ameyo | DMA Phase 3 | B10: 8
A11: In Progress | B11: 8
A12: AI Automation — Ameyo Call Details Report Downloader | B12: 7
A13: In Progress | B13: 7
... A38: Grand Total | B38: 187.02198

Sheet All Sales
A1: Group | B1: Deals | C1: Category | D1: BUSINESS NAME | E1: Title | F1: Fulla Name | G1: Designation | H1: Phone | I1: Mobile | J1: Email | K1: Website | L1: Sale Status | M1: Service | N1: Techstack | O1: Cost | P1: Sale Date | Q1: Business Type | R1: DSR | S1: Lead Created Date | T1: Lead ID | U1: Lead Type | V1: BDR | W1: Payment Frequency | X1: Payment Type
A2: BABYPINK | B2: 1 | C2: Beauty, Hair & Wellness | D2: BABYPINK | K2: No Website | L2: Sale Processed | M2: Web Dev | N2: Custom | O2: £250.00 | P2: 44927 | Q2: New | R2: Other | S2: 44927 | U2: Fresh | V2: Other | W2: One-off - Partial | X2: One-off
A3: ANDY PARK PROMOTIONS | B3: 1 | C3: Entertainment Agency | D3: ANDY PARK PROMOTIONS | E3: Mr | F3: Andy Park | G3: Owner | H3: 1228818182 | I3: 7368361254 | J3: andypark8181@gmail.com | K3: https://www.andyparkpromotions.co.uk/ | L3: Sale Processed | M3: Digital Marketing | N3: SMO | O3: £250.00 | P3: 45007 | Q3: New | R3: Akram | S3: 44999 | T3: 203 | U3: Fresh | V3: Other | W3: Monthly | X3: Recurring
A4: LOCKMAN247 | B4: 1 | C4: Security & Safety | D4: LOCKMAN247 | E4: Mr | F4: Lee Bennett | G4: Director | H4: 1270342247 | I4: 7730582469 | J4: info@lockman247.co.uk | K4: https://lockman247.co.uk/ | L4: Sale Processed | M4: Web Dev | N4: Wordpress | O4: £300.00 | P4: 45029 | Q4: New | R4: Akram | S4: 45016 | T4: 204 | U4: Fresh | V4: Other | W4: One-off - Partial | X4: One-off
A5: LOCKMAN247 | B5: 2 | C5: Security & Safety | D5: LOCKMAN247 | E5: Mr | F5: Lee Bennett | G5: Director | H5: 1270342247 | I5: 7730582469 | J5: info@lockman247.co.uk | K5: https://lockman247.co.uk/ | L5: Sale Processed | M5: Digital Marketing | N5: SEO | O5: £250.00 | P5: 45029 | Q5: Cross-Sell | R5: Akram | S5: 45016 | T5: 204 | U5: Fresh | V5: Other | W5: Monthly | X5: Recurring
A6: METALMASTER PROMOTIONS UK LTD | B6: 1 | C6: Specialist Trades | D6: METALMASTER PROMOTIONS UK LTD | E6: Mr | F6: Paul Sammut | G6: Director | H6: 2086705042 | I6: 7986003426 | J6: info4u2@metalmaster.co.uk | K6: https://www.metalmaster.co.uk/ | L6: Sale Processed | M6: Digital Marketing | N6: SMO | O6: £100.00 | P6: 45048 | Q6: New | R6: Akram | S6: 45035 | T6: 252 | U6: Fresh | V6: Other | W6: Monthly | X6: Recurring
A7: DW STORE | B7: 1 | C7: Clothing | D7: D W Store | E7: Mr | F7: Dudley Washington | G7: Director | I7: 7774831154 | J7: alexlawson660@gmail.com | K7: No Website | L7: Sale Processed | M7: Web Dev | N7: Wordpress | O7: £400.00 | P7: 45083 | Q7: New | R7: Akram | S7: 45254 | T7: 351 | U7: Fresh | V7: Other | W7: One-off - Partial | X7: One-off
A8: Coulon Stone Limited | B8: 1 | C8: Tiling, Bathrooms & Kitchens | D8: Coulon Stone Limited | E8: Mr | F8: Simon Coulon | G8: Director | H8: 1494484333 | I8: 7971863682 | J8: simon@coulonstone.com | K8: https://coulonstone.com/ | L8: Sale Processed | M8: Web Dev | N8: Wordpress | O8: £300.00 | P8: 45106 | Q8: New | R8: Akram | S8: 45069 | T8: 205 | U8: Fresh | V8: Other | W8: One-off - Partial | X8: One-off
A9: Coulon Stone Limited | B9: 2 | C9: Tiling, Bathrooms & Kitchens | D9: Coulon Stone Limited | E9: Mr | F9: Simon Coulon | G9: Director | H9: 1494484333 | I9: 7971863682 | J9: simon@coulonstone.com | K9: https://coulonstone.com/ | L9: Sale Processed | M9: Digital Marketing | N9: SEO | O9: £250.00 | P9: 45106 | Q9: Cross-Sell | R9: Akram | S9: 45069 | T9: 205 | U9: Fresh | V9: Other | W9: Monthly | X9: Recurring
A10: ALAN LAM | B10: 1 | C10: Health & Supplements | D10: ALAN LAM | E10: Mr | F10: Alan Lam | G10: Owner | H10: 2086532751 | I10: 7947000568 | J10: admin@alan-lam.co.uk | K10: https://www.alan-lam.co.uk/ | L10: Sale Processed | M10: Web Dev | N10: Wordpress | O10: £300.00 | P10: 45112 | Q10: New | R10: Akram | S10: 45110 | T10: 207 | U10: Fresh | V10: Akram | W10: One-off - Partial | X10: One-off
A11: 108 BUILDERS LIMITED | B11: 1 | C11: Builders & General Construction | D11: 108 BUILDERS LIMITED | E11: Mr | F11: Bogdan Tomaszewicz | G11: Director | I11: 7722242035 | J11: bogdan@108builders.co.uk | K11: https://108builders.co.uk/ | L11: Sale Processed | M11: Web Dev | N11: Custom | O11: £300.00 | P11: 45149 | Q11: New | R11: Akram | S11: 45161 | T11: 31 | U11: Fresh | V11: Akram | W11: One-off - Partial | X11: One-off
A12: M - CABS LYMEREGIS | B12: 1 | C12: Taxi, Chauffeur & Transport | D12: M - CABS LYMEREGIS | E12: Mr | F12: Christian Joseph | G12: Owner | H12: 1297442222 | I12: 7801996414 | J12: vonmerowing@gmail.com | K12: https://mcabslymeregis.co.uk/ | L12: Sale Processed | M12: Web Dev | N12: Wordpress | O12: £250.00 | P12: 45166 | Q12: New | R12: Akram | S12: 45161 | T12: 28 | U12: Fresh | V12: Other | W12: One-off - Partial | X12: One-off
A13: Superhouse Group | B13: 1 | C13: Footwear | D13: NOTHWEST TERRITORY | E13: Mr | F13: Sharooq Imam | G13: Manager | H13: 1327703841 | I13: 7876366810 | J13: sharooq@patrickshoes.co.uk | K13: https://northwestterritory.co.uk/ | L13: Sale Processed | M13: Web Dev | N13: Shopify | O13: £400.00 | P13: 45177 | Q13: New | R13: Akram | S13: 45078 | T13: 253 | U13: Fresh | V13: Akram | W13: One-off - Partial | X13: One-off
A14: PAUL BAILEY HOME EXTENSIONS | B14: 1 | C14: Builders & General Construction | D14: PAUL BAILEY HOME EXTENSIONS | E14: Mr | F14: Paul Bailey | G14: Owner | H14: 1277532991 | I14: 7545307419 | J14: Info@paulbailey.info | K14: https://loftconversionsessex.co.uk/ | L14: Sale Processed | M14: Digital Marketing | N14: SEO | O14: £150.00 | P14: 45196 | Q14: New | R14: Akram | S14: 45197 | T14: 18 | U14: Fresh | V14: Other | W14: Monthly | X14: Recurring
A15: MASSEY PROPERTY | B15: 1 | C15: Property & Real Estate | D15: MASSEY PROPERTY | E15: Mrs | F15: Joanna Martin | G15: Owner | H15: 1273727278 | J15: jo.blaise@masseyproperty.com | K15: https://www.masseyproperty.com/ | L15: Sale Processed | M15: Digital Marketing | N15: SEO | O15: £400.00 | P15: 45197 | Q15: New | R15: Akram | S15: 45098 | T15: 115 | U15: Fresh | V15: Other | W15: Monthly | X15: Recurring
A16: LB TAXI | B16: 1 | C16: Taxi, Chauffeur & Transport | D16: L B Taxis Ltd | E16: Mr | F16: Mohammed Belal Ahmed | G16: Director | H16: 1525464646 | I16: 7846373112 | J16: belal-mhd@hotmail.co.uk | K16: https://lbtaxi.co.uk/ | L16: Sale Processed | M16: Web Dev | N16: Wordpress | O16: £300.00 | P16: 45209 | Q16: New | R16: Akram | S16: 45264 | T16: 137 | U16: Fresh | V16: Other | W16: One-off - Partial | X16: One-off
A17: XTRA SENSE | B17: 1 | C17: Security & Safety | D17: XTRA SENSE | E17: Mr | F17: Peter Hutcheson | G17: Owner | H17: 140443366 | I17: 140443366 | J17: security@xtra-sense.co.uk | K17: https://www.xtra-sense.co.uk/ | L17: Sale Processed | M17: Web Dev | N17: Wordpress | O17: £250.00 | P17: 45215 | Q17: New | R17: Akram | S17: 45215 | T17: 117 | U17: Fresh | V17: Other | W17: One-off - Partial | X17: One-off
A18: AHIMSA LONDON LIMITED | B18: 1 | C18: Jewellery | D18: LABMADE DIAMOND | E18: Mr | F18: Nerav Mehta | G18: Director | I18: 7824345308 | J18: ahimsalondon@gmail.com | K18: https://www.labmadediamonds.co.uk/ | L18: Sale Processed | M18: Web Dev | N18: Wordpress | O18: £3,000.00 | P18: 45222 | Q18: New | R18: Other | S18: 45296 | T18: 126 | U18: Fresh | V18: Other | W18: One-off - Partial | X18: One-off
A19: AHIMSA LONDON LIMITED | B19: 2 | C19: Jewellery | D19: LABMADE DIAMOND | E19: Mr | F19: Nerav Mehta | G19: Director | I19: 7824345308 | J19: ahimsalondon@gmail.com | K19: https://www.labmadediamonds.co.uk/ | L19: Sale Processed | M19: Digital Marketing | N19: SEO | O19: £799.00 | P19: 45222 | Q19: Cross-Sell | R19: Akram | S19: 45296 | T19: 126 | U19: Fresh | V19: Other | W19: Monthly | X19: Recurring
A20: Plan And Build London Ltd | B20: 1 | C20: Education & Training | D20: REVISE WITH ME | E20: Mr | F20: Tomi Adebayo | G20: Director | I20: 7961161810 | J20: tomi@planandbuild.net | K20: https://revisewithme.com/ | L20: Sale Processed | M20: Web Dev | N20: Custom | O20: £8,500.00 | P20: 45223 | Q20: New | R20: Akram | S20: 45223 | T20: 92 | U20: Fresh | V20: Other | W20: One-off - Partial | X20: One-off
A21: M & A STRUCTURAL DESIGN | B21: 1 | C21: Engineering & Structural | D21: M&A STRUCTURAL DESIGN SERVICES LIMITTED | E21: Mr | F21: Ahmed Yasser | G21: Director | H21: 1865600067 | J21: info@masds.co.uk | K21: https://masds.co.uk/ | L21: Sale Processed | M21: Web Dev | N21: Wordpress | O21: £300.00 | P21: 45224 | Q21: New | R21: Akram | S21: 45566 | U21: Fresh | V21: Other | W21: One-off - Partial | X21: One-off
A22: BEST SIZZLER | B22: 1 | C22: Food & Hospitality | D22: BEST SIZZLER LIMITED | E22: Mr | F22: Arbaaz Ahmed | I22: 7447907544 | J22: arbaz007o1@gmail.com | K22: No Website | L22: Sale Processed | M22: Web Dev | N22: Custom | O22: £1,000.00 | P22: 45245 | Q22: New | R22: Akram | S22: 45566 | T22: FRID002128 | U22: Fresh | V22: Tamal | W22: One-off - Partial | X22: One-off
A23: KAD ELECTRICALS | B23: 1 | C23: Electrical Services | D23: KAD ELECTRICIANS LTD | E23: Mr | F23: Kastro Pashku | G23: Director | I23: 7429540950 | J23: info@kadelectricians.co.uk | K23: https://kadelectricians.co.uk/ | L23: Sale Processed | M23: Web Dev | N23: Wordpress | O23: £250.00 | P23: 45250 | Q23: New | R23: Akram | S23: 45566 | T23: FRID002129 | U23: Fresh | V23: Other | W23: One-off - Partial | X23: One-off
A24: DA ROWLEY | B24: 1 | C24: Builders & General Construction | D24: D A ROWLEY LIMITED | E24: Mr | F24: Andrew Rowley | G24: Director | I24: 7976762990 | J24: arowley07@aol.com | K24: http://www.darowley.com/ | L24: Sale Processed | M24: Web Dev | N24: Wordpress | O24: £250.00 | P24: 45259 | Q24: New | R24: Akram | S24: 45566 | T24: FRID002130 | U24: Fresh | V24: Other | W24: One-off - Partial | X24: One-off
A25: PATCHITT JOINERY | B25: 1 | C25: Carpentry & Joinery | D25: A AND C R PATCHITT | E25: Mr | F25: Samuel Patchitt | G25: Owner | H25: 1159390011 | I25: 7932578092 | J25: sam@patchitt-joinery.co.uk | K25: https://patchitt-joinery.co.uk/ | L25: Sale Processed | M25: Web Dev | N25: Wordpress | O25: £250.00 | P25: 45260 | Q25: New | R25: Akram | S25: 45566 | T25: FRID002131 | U25: Fresh | V25: Other | W25: One-off - Partial | X25: One-off
A26: 10 PLUS ONE STORE | B26: 1 | C26: Retail & E-Commerce | D26: 10 PLUS ONE STORE | E26: Mr | F26: Kamal Jeet Singh | G26: Director | I26: 7366146695 | J26: 11elevenmotion@gmail.com | K26: https://10plusonestore.co.uk/ | L26: Sale Processed | M26: Web Dev | N26: Wordpress | O26: £1,200.00 | P26: 45278 | Q26: New | R26: Akram | S26: 45566 | T26: FRID002132 | U26: Fresh | V26: Tamal | W26: One-off - Partial | X26: One-off
A27: SPLENDENT TILE & PAINT LTD | B27: 1 | C27: Tiling, Bathrooms & Kitchens | D27: SPLENDENT TILE & PAINT LTD | E27: Mr | F27: Sohan Singh | G27: Director | I27: 7438564925 | J27: splendent1984@gmail.com | K27: https://splendenttile.co.uk/ | L27: Sale Processed | M27: Digital Marketing | N27: SEO | O27: £150.00 | P27: 45313 | Q27: New | R27: Aryan | S27: 45632 | T27: FRID002948 | U27: Fresh | V27: Deepak | W27: Monthly | X27: Recurring
A28: Superhouse Group | B28: 4 | C28: Footwear | D28: AMEN SHOES - PATRICK SHOES LIMITED | E28: Mr | F28: Noain Bakshi | G28: Director | H28: 1327703841 | J28: noain@patrickshoes.co.uk | K28: https://amenshoesuk.co.uk/ | L28: Sale Processed | M28: Web Dev | N28: Shopify | O28: £400.00 | P28: 45322 | Q28: New | R28: Akram | S28: 45566 | T28: FRID002115 | U28: Reference | V28: Akram | W28: One-off - Partial | X28: One-off
A29: Superhouse Group | B29: 5 | C29: Footwear | D29: AMEN SHOES - PATRICK SHOES LIMITED | E29: Mr | F29: Noain Bakshi | G29: Director | H29: 1327703841 | J29: noain@patrickshoes.co.uk | K29: https://amenshoesuk.co.uk/ | L29: Sale Processed | M29: Digital Marketing | N29: SEO | O29: £200.00 | P29: 45322 | Q29: Cross-Sell | R29: Akram | S29: 45566 | T29: FRID002115 | U29: Reference | V29: Akram | W29: Monthly | X29: Recurring
A30: SHOREDITCH INN LIMITED | B30: 1 | C30: Food & Hospitality | D30: SHOREDITCH INN LIMITED | E30: Mr | F30: Praveen Kishore | G30: Director | I30: 7830114154 | J30: raj@shoreditchinn.com | K30: https://shoreditchinn.com/ | L30: Sale Processed | M30: Digital Marketing | N30: SEO | O30: £300.00 | P30: 45334 | Q30: New | R30: Akram | S30: 45566 | T30: FRID002136 | U30: Reference | V30: Tamal | W30: Monthly | X30: Recurring
A31: SCOTTAXI | B31: 1 | C31: Taxi, Chauffeur & Transport | D31: SCOT TAXI | E31: Mr | F31: Nikolay Kostov | G31: Owner | I31: 7928086205 | J31: booking@scottaxi.com | K31: https://scottaxi.com/ | L31: Sale Processed | M31: Web Dev | N31: Wordpress | O31: £300.00 | P31: 45385 | Q31: New | R31: Akram | S31: 45566 | T31: FRID002137 | U31: Fresh | V31: Other | W31: One-off - Partial | X31: One-off
A32: SCOTTAXI | B32: 2 | C32: Taxi, Chauffeur & Transport | D32: SCOT TAXI | E32: Mr | F32: Nikolay Kostov | G32: Owner | I32: 7928086205 | J32: booking@scottaxi.com | K32: https://scottaxi.com/ | L32: Sale Processed | M32: Digital Marketing | N32: SEO | O32: £150.00 | P32: 45385 | Q32: Cross-Sell | R32: Akram | S32: 45566 | T32: FRID002137 | U32: Fresh | V32: Other | W32: Monthly | X32: Recurring
A33: Superhouse Group | B33: 6 | C33: Footwear | D33: SILVER STREET - SUPERHOUSE (UK) LIMITED | E33: Mr | F33: Akbar Waris | K33: https://www.silverstreetlondon.co.uk/ | L33: Sale Processed | M33: Web Dev | N33: Shopify | O33: £400.00 | P33: 45390 | Q33: New | R33: Akram | S33: 45566 | U33: Reference | V33: Akram | W33: One-off - Partial | X33: One-off
A34: Superhouse Group | B34: 7 | C34: Footwear | D34: SILVER STREET - SUPERHOUSE (UK) LIMITED | E34: Mr | F34: Akbar Waris | K34: https://www.silverstreetlondon.co.uk/ | L34: Sale Processed | M34: Digital Marketing | N34: SEO | O34: £200.00 | P34: 45390 | Q34: Cross-Sell | R34: Akram | S34: 45566 | U34: Reference | V34: Akram | W34: Monthly | X34: Recurring
A35: Superhouse Group | B35: 8 | C35: Footwear | D35: BRIGGS INDUSTRIAL FOOTWEAR LIMITED | E35: Mr | F35: Akbar Waris | K35: https://briggssafetywear.com/ | L35: Sale Processed | M35: Web Dev | N35: Shopify | O35: £600.00 | P35: 45412 | Q35: New | R35: Akram | S35: 45566 | T35: FRID002169 | U35: Reference | V35: Akram | W35: One-off - Partial | X35: One-off
A36: Superhouse Group | B36: 9 | C36: Footwear | D36: BRIGGS INDUSTRIAL FOOTWEAR LIMITED | E36: Mr | F36: Akbar Waris | K36: https://briggssafetywear.com/ | L36: Sale Processed | M36: Digital Marketing | N36: SEO | O36: £200.00 | P36: 45412 | Q36: Cross-Sell | R36: Akram | S36: 45566 | T36: FRID002169 | U36: Reference | V36: Akram | W36: Monthly | X36: Recurring
A37: MILTON MENSWEAR LIMITED | B37: 1 | C37: Clothing | D37: MILTON MENSWEAR LIMITED | E37: Mr | F37: Jeremy John Lawson | G37: Director | H37: 1202292895 | I37: 7779777112 | J37: sales@alfa-menswear.com | K37: https://www.alfa-menswear.com/ | L37: Sale Processed | M37: Web Dev | N37: Custom | O37: £150.00 | P37: 45415 | Q37: New | R37: Akram | S37: 45572 | T37: FRID002174 | U37: Fresh | V37: Other | W37: One-off - Partial | X37: One-off
A38: Superhouse Group | B38: 10 | C38: Footwear | D38: SADDLER ACCESSORIES LTD | E38: Mr | F38: Gavin Watson | G38: Manager | H38: 1327221187 | I38: 7951635585 | J38: gavin@saddler-accessories.com | K38: https://saddler-accessories.com/ | L38: Sale Processed | M38: Web Dev | N38: Shopify | O38: £600.00 | P38: 45433 | Q38: New | R38: Akram | S38: 45483 | T38: FRID000202 | U38: Fresh | V38: Akram | W38: One-off - Partial | X38: One-off
A39: Superhouse Group | B39: 11 | C39: Footwear | D39: SADDLER ACCESSORIES LTD | E39: Mr | F39: Gavin Watson | G39: Manager | H39: 1327221187 | I39: 7951635585 | J39: gavin@saddler-accessories.com | K39: https://saddler-accessories.com/ | L39: Sale Processed | M39: Digital Marketing | N39: SEO | O39: £200.00 | P39: 45433 | Q39: Cross-Sell | R39: Akram | S39: 45483 | T39: FRID000202 | U39: Fresh | V39: Akram | W39: Monthly | X39: Recurring
A40: SOS PLUMBING SERVICES LTD | B40: 1 | C40: Plumbing, Heating & Gas | D40: SOS PLUMBING SERVICES LTD | E40: Mr | F40: Claudiu Stefan Rosca | G40: Director | I40: 7932439650 | J40: plumbingservices83@gmail.com | K40: https://sosplumberservices.co.uk/ | L40: Sale Processed | M40: Web Dev | N40: Wordpress | O40: £250.00 | P40: 45477 | Q40: New | R40: Akram | S40: 45468 | T40: FRID000077 | U40: Fresh | V40: Ibrahim | W40: One-off - Partial | X40: One-off | Y40: 241137 | AA40: £300.00 | AB40: Paid
...
